<!-- =========================================================================== #
# Project:        Planar 1DOF Robot
# Title:          A Planar 1DOF robot with torque actuators
# Author:         Moses C. Nah
# Creation Date:  Wednesday, Oct 19th, 2022
# ============================================================================= #  -->

<mujoco model="1DOF_Planar_Robot">

  <compiler inertiafromgeom = "auto" angle = "radian"/>

   <!-- (semi-) implicit Euler method was used for the integrator with time step of 0.1ms -->
	<option timestep='0.01' iterations='50' integrator='Euler' collision='all' gravity="0 0 0"/>

  <asset>
    <!-- Texture of the surrounding sky box
         setting everything as white-ish color for better visualization -->
     <texture type="skybox"
              builtin="flat"
              rgb1="1 1 1"
              rgb2="1 1 1"
              width="100"
              height="100"/>

     <!-- Joint and Limb Color -->
		 <material name="JointColor" 		 rgba="0.75 0.0 0.75 1" />
		 <material name="LimbColor" 		 rgba="0.1 0.1 0.1 1" />

  </asset>

  <worldbody>

    
		<body name='body1' pos='0 0 0' euler='0 0 0'>
      <joint name='joint1' ref='0' type='hinge' stiffness='0' pos='0 0 0' axis='0 0 1' />
			<inertial pos='0.5 0 0' mass='1' diaginertia='1 1 1'/>
			<geom name='geom1' type='sphere' pos='0 0 0' material='JointColor' size='0.08' mass='0'/>
			<geom type='cylinder' fromto='0 0 0 1 0 0'   material='LimbColor'  size='0.04' mass='0'/>
      <geom name='geom2' type='sphere' pos='1 0 0' material='JointColor' size='0.08' mass='0'/>        
      <site name="site_end_effector" pos='1 0 0'/>
  </body>


  </worldbody>

  <actuator>
		  <motor joint='joint1' name='motor_joint1' forcelimited='false'/>
  </actuator>

</mujoco>
